Workbook

Sheet About
A1: BGDPbES BAU Guaranteed Dispatch Percentage by Electricity Source | B1: Vermont | C1: 2026-09-02 | K1: Alabama | L1: AL
A2: Active state: cell B1 (full state name). B2 resolves the abbreviation used by the calc tabs. | B2: =INDEX(L1:L48,MATCH(B1,K1:K48,0)) -> VT | K2: Arizona | L2: AZ
K3: Arkansas | L3: AR
A4: Purpose: | B4: Guarantee a portion of coal dispatch. EPS under-dispatches coal ~-27% nationally vs EIA-923 2025 (gas +3.4%) because annual-average least-cost dispatch cannot represent the non-price factors that kept the real coal fleet at ~50% CF (seasonal gas price spikes hidden by the annual average, utility self-scheduling, coal supply contracts, minimum-run and pipeline constraints). The BFPaT electricity-sector fuel prices were audited 2026-07-22 and are correct (EIA EPA 7.17/7.20 2024 anchors x CPI-U 2012$ deflator, STEO Jun-2026 2025 step of gas x1.41 / coal x0.98), so the calibration lever is guaranteed dispatch, not prices. | K4: California | L4: CA
A5: Mechanism: | B5: Guaranteed dispatch = capacity x expected hourly CF x BGDPbES, per hour (proportionally scaled back only if hourly demand is exceeded); the remaining capacity still bids into RPS and least-cost dispatch, up to the full expected CF. Because HYECFCA anchors start-year expected CFs to 2025 observed CFs, BGDPbES[coal]=X floors start-year coal generation at X x (2025 observed generation) while leaving (1-X) to economics. | K5: Colorado | L5: CO
A6: Layout (2026-08-21): | B6: Every output value flows from exactly two tabs. `Defaults` holds ONE value per tech -- the value used for every state with no calibrated override (builder constants, with a note per tech). `Tuned` holds the long-format state|tech calibrated overrides: the per-state coal/gas guarantees from the tuning-results CSV (qc/bgd_tune_results_merged_2026-08-14.csv), the peaker exceptions (MT/ND/VA/WA/WV), and the hydro exceptions (SD 0.75, WA 0.0). The output formula is IFERROR(Tuned lookup, Defaults lookup), plus the Keys pin table (2025-only), the hydro cap, and the VT hydro ramp. The former Current_BGDPbES tab (deployed CSVs compiled verbatim) was REMOVED: it made every rebuild re-import whatever was deployed, so hand decisions could be silently overwritten. Tuning passes cannot overwrite Defaults-driven rows -- the probe/tune scripts patch only their named coal/gas/peaker row in the run tree (and restore it), and the results CSVs carry only the five g_* columns. | K6: Connecticut | L6: CT
A7: Zeroed techs (2026-08-21): | B7: Six never-built techs are ZERO in every year and every state (Olivia): hard coal w CCS, natural gas combined cycle w CCS, biomass w CCS, lignite w CCS, small modular reactor, hydrogen combined cycle. Their previous values (0.15/0.15/1.0/1.0/0.0/1.0) were inherited verbatim from the eps-us national template, never a state calibration, and a nonzero guarantee on a tech EPS may BUILD in a policy scenario forces that new capacity to run near must-run from its first year, ahead of least-cost dispatch. Hydrogen combustion turbine is deliberately NOT zeroed and keeps its 1.0. | K7: Delaware | L7: DE
A8: Values: | B8: The four coal/gas rows (hard coal, lignite, NG steam turbine, NGCC) are 2025-ONLY (Olivia 2026-08-17): zero in every year except 2025, where each state takes its pin-table value if pinned, else its Tuned value, else the Defaults value (0 = no floor). After the calibrated start year the model determines its own coal/gas mix. The tuned values are the Phase C pass (2026-08-14, coal/gas balance on climate-0813: EQUAL relative error on coal and gas given the demand level, price gate <=5%), with earlier passes carried forward for untouched states. Hydro keeps the flat 0.90 convention; NG peaker keeps its flat per-state values (structural convention, not calibration). | K8: Florida | L8: FL
A9: VT hydro ramp: | B9: VT hydro = the Keys-tab F:G ramp block (Keys hydro_ramp_state, calibrated 2026-08-11): 0 through 2025, 0.3/0.5/0.7/0.85 over 2026-29, 0.9 from 2030. VT hydro dispatch otherwise collapses post-2025 in BAU and ClimateAmbition (must-take builds saturate the fixed requirement and wholesale falls to ~$0-9/MWh, below any defensible HOC); the ramp floors it at ~1.0 TWh BAU / >=0.78 TWh ClimateAmbition while leaving 2025 dispatch and prices byte-identical to the current calibration. A flat guarantee was tested and rejected (reorders 2025: guaranteed dispatch runs ahead of the RPS pass, g=0.7 pushed wind -22% vs observed); so was HOC 35 (zero dispatch effect, 2025 wholesale -15%). Evidence: docs/findings/vt-hydro-guarantee-ramp-2026-08-11.md. | K9: Georgia | L9: GA
A10: Hydro guarantee cap (2026-08-13): | B10: Olivia set a standing MAX of 0.90 on BGDPbES[hydro] -- no state should reach 1.0, because a near-must-run hydro fleet is removed from marginal price formation. ID was the only state above the cap (1.0) and is now 0.90. That value was LOAD-BEARING, not decorative: removing it alone moved ID hydro +1.94% -> -7.18% vs EIA-923 2025, so it was PAIRED with HOC 80 -> 35, which recovers it to +1.30% (price gate PASS). SD is deliberately LEFT at 0.75 -- raising it to 0.90 pinned SD hydro at +10.45% (= 0.90 x SD potential 4.633, above its EIA benchmark), and 0.75 already satisfies the cap. GENERAL LESSON: the guarantee denominator is the state hydro POTENTIAL, not the EIA benchmark, so "EPS/EIA > guarantee" does NOT prove a guarantee is non-binding -- test by running it. WA (0.0) and VT (ramp) keep their documented exceptions. Evidence: docs/findings/start-year-dispatch-calibration-2026-08-13.md. | K10: Idaho | L10: ID
A11: 2025 pin table (2026-08-17): | B11: Twelve state|tech guarantees are overridden in 2025 ONLY (Keys I:J pin table + pin_year; the output-tab year formula applies them). Two Olivia decisions merged: (1) WA hard coal 0.947 / NGCC 0.795 — the US_ClimateAmbition scenario shifts ~6 TWh of WA start-year dispatch from gas into hydro at the same $40 HOC, and 2025 is history, so observed dispatch is pinned; from 2026 policy hydro flexes freely (75.9 TWh in 2026, inside WA's 60.7-91.8 TWh 2010-24 range). (2) The option-B coal/gas retune ("equal % error on coal and gas, given the demand level"): MT/AZ/IL/IA/SC/WY hard-coal, KS/CO/MN NGCC, ND peaker (ND has no NGCC fleet — its NGCC floor was measured inert). Spreads closed to <=1.6pp everywhere except WY (4.0pp, price-gate-limited). Pins, not flat floors, because the 2025 response is identical while flat floors carry measured late-year price costs (WY ~29%, MN ~21% industry 2050). Evidence: qc/bgd_tune_results_optionb*_2026-08-17.csv, docs/findings/wa-2025-guarantee-pin-2026-08-17.md. | K11: Illinois | L11: IL
A12: Hydro 2025 pins (2026-08-24): | B12: Twelve hydro crowd-out states get a 2025-ONLY hydro pin (Keys I:J) at g = EIA-923-2025 target / expected output, paired with HOC 62 (NV 45; NV needs no pin -- its 0.9 floor already equals its target). Mechanism: the 2025-only coal/gas guarantees expire in 2026 and hydro at a low HOC under-prices carbon-loaded/forecast-priced fossil, jumping to its availability on flat capacity (AL +121%, AZ +174%, NV +205% vs target over 2026-29 on climate-0824). The pin holds 2025 exact (probes: -0.0% in 11 states, SD -0.5%) with no wind/solar displacement (SD mildest exception, -4%), and the raised HOC returns 2026+ dispatch to economics: hydro lands on its 0.9 out-year floor (-1% to -17% vs target) and fossil recovers (CA gas 2026: 49 -> 76 TWh). Pins may exceed the 0.90 cap in the pin year ONLY (Olivia direction 2026-08-24). OR joined the pinned set by Olivia decision same day (pin 0.9707 = target/expected 29.564, + HOC 62): the fix makes all four OR generation series realistic (hydro flat ~27-28 TWh, gas glides per HB 2021, wind/solar build more) with 2025-26 retail unchanged; 2028-29 retail +7-13% is the accepted cost, and 2030-50 residential lands INSIDE the waiver-corrected price band (the old baseline was registered 19-36% low there; industrial likely overshoots its band). WA is the one hydro-dominant state with NO pin: guaranteed hydro displaces its must-take wind (tested -41%), so it runs the HOC-55 compromise instead. Campaign evidence: ~32 BAU probe runs 2026-08-24, docs/findings/bau-fossil-dispatch-cliffs-2026-08-24.md. | K12: Indiana | L12: IN
A13: Expected impact: | B13: At 0.90 with the current -2.8% demand anchor: national coal rises from ~531 to a >=657 TWh floor (-10% vs 923ER instead of -27%); displaced generation comes mostly out of gas (~+3.4% -> ~-4%). After the November SEDS 2025 demand re-anchor restores ~119 TWh of demand, least-cost refills gas toward actuals. | K13: Iowa | L13: IA
A14: CAVEAT - policy runs: | B14: BGDPbES applies in ALL scenarios, not just BAU. A coal floor mutes price-driven coal redispatch (e.g. carbon tax) until capacity actually retires: policy can still retire coal (guaranteed MWh fall with capacity) but cannot dispatch surviving coal below the floor. Same trade-off already accepted for nuclear (1.0), hydro (0.9), peakers (1.0) and documented for HYECFCA. Staff decision on the fraction (0 restores pure least-cost). | K14: Kansas | L14: KS
A15: Caveats - data: | B15: Floor quality inherits HYECFCA/SYSHECF quality: 2025 observed coal CFs include 2025-specific outages and the thin-demand year. States where coal is already economic in EPS (MO, KY, WY: coal beats gas on fuel cost) are unaffected in practice -- least-cost already dispatches above the floor there. Verify against primary sources (EIA-923/860, EPA 7.17/7.20) before adopting; draft for staff review. | K15: Kentucky | L15: KY
A16: Rebuild: | B16: python outputs/BGDPbES/_build_bgdpbes_workbook.py | K16: Louisiana | L16: LA
K17: Maine | L17: ME
K18: Maryland | L18: MD
K19: Massachusetts | L19: MA
K20: Michigan | L20: MI
K21: Minnesota | L21: MN
K22: Mississippi | L22: MS
K23: Missouri | L23: MO
K24: Montana | L24: MT
K25: Nebraska | L25: NE
K26: Nevada | L26: NV
K27: New Hampshire | L27: NH
K28: New Jersey | L28: NJ
... K48: Wyoming | L48: WY

Sheet Keys
A1: category | B1: key | C1: value | D1: description | F1: ramp_year | G1: hydro_ramp_value | I1: pin_key (state|tech) | J1: pin_value
A2: gate | B2: hydro_ramp_state | C2: VT | D2: State whose hydro guarantee is YEAR-VARYING (calibrated 2026-08-11): VT hydro dispatch collapses post-2025 in BAU and ClimateAmbition (must-take builds saturate the requirement; wholesale ~$0-9/MWh by 2030, so no HOC can carry it). The ramp in the year block to the right floors hydro from 2026 on while leaving the calibrated 2025 start year untouched -- a flat guarantee was tested and reorders 2025 dispatch (g=0.7 pushed wind -22% vs observed: guaranteed dispatch runs ahead of the RPS pass). Evidence: docs/findings/vt-hydro-guarantee-ramp-2026-08-11.md. | F2: 2021 | G2: 0 | I2: AL|hydro | J2: 1
A3: gate | B3: hydro_guarantee_cap | C3: 0.9 | D3: Standing MAX on BGDPbES[hydro] (Olivia, 2026-08-13): no state reaches 1.0, because near-must-run hydro is removed from marginal price formation and accurate prices rank above accurate hydro. Applied as MIN(value, this cap) in the Output hydro row. Bound ID only (was 1.0 -> 0.90, PAIRED with HOC 80 -> 35 because the 1.0 was load-bearing: removing it alone moved ID hydro +1.94% -> -7.18% vs EIA-923 2025). SD stays 0.75 (already under the cap, Tuned-tab row). NOTE the guarantee denominator is state hydro POTENTIAL, not the EIA benchmark, so a ratio test cannot prove a guarantee non-binding -- run it. Evidence: docs/findings/start-year-dispatch-calibration-2026-08-13.md | F3: 2022 | G3: 0 | I3: AR|hydro | J3: 1
A4: gate | B4: pin_year | C4: 2025 | D4: The single year the I:J pin table applies to (the calibration start year). Coal/gas pins: WA policy-scenario hydro/gas fix + the option-B coal/gas retune (Olivia decisions 2026-08-17); 2025 dispatch response is identical to a flat floor, and pins avoid the measured late-year price costs (WY flat ~29%, MN flat ~21% industry 2050). HYDRO pins added 2026-08-24 (Olivia: guarantee hydro in the start year, calibrate HOC on 2026-29): 13 crowd-out states pinned at target/expected (1.0 everywhere except SD 0.9917 and OR 0.9707), paired with HOC 62 (NV 45, no pin needed). Hydro pins are UNCAPPED in the pin year by the same direction; the 0.90 cap governs all other years. Evidence: qc/bgd_tune_results_optionb*_2026-08-17.csv, docs/findings/wa-2025-guarantee-pin-2026-08-17.md, and docs/findings/bau-fossil-dispatch-cliffs-2026-08-24.md. | F4: 2023 | G4: 0 | I4: AZ|hydro | J4: 1
F5: 2024 | G5: 0 | I5: CA|hydro | J5: 1
F6: 2025 | G6: 0 | I6: CO|hydro | J6: 1
F7: 2026 | G7: 0.3 | I7: GA|hydro | J7: 1
F8: 2027 | G8: 0.5 | I8: KY|hydro | J8: 1
F9: 2028 | G9: 0.7 | I9: LA|solar PV | J9: 1
F10: 2029 | G10: 0.85 | I10: MA|solar PV | J10: 1
F11: 2030 | G11: 0.9 | I11: MN|hydro | J11: 1
F12: 2031 | G12: 0.9 | I12: MT|onshore wind | J12: 1
F13: 2032 | G13: 0.9 | I13: NC|hydro | J13: 1
F14: 2033 | G14: 0.9 | I14: NV|solar PV | J14: 1
F15: 2034 | G15: 0.9 | I15: OK|hydro | J15: 1
F16: 2035 | G16: 0.9 | I16: OK|onshore wind | J16: 1
... F21: 2040 | G21: 0.9 | I21: WV|onshore wind | J21: 1
F22: 2041 | G22: 0.9
F23: 2042 | G23: 0.9
F24: 2043 | G24: 0.9
F25: 2044 | G25: 0.9
F26: 2045 | G26: 0.9
F27: 2046 | G27: 0.9
F28: 2047 | G28: 0.9
F29: 2048 | G29: 0.9
F30: 2049 | G30: 0.9
F31: 2050 | G31: 0.9

Sheet Defaults
A1: tech | B1: default_value | C1: note
A2: hard coal | B2: 0 | C2: Coal/gas guarantees are 2025-only calibration (Olivia 2026-08-17): all years except 2025 are structurally 0, and an untuned/unpinned state has no 2025 floor either. Per-state 2025 values on Tuned/pins.
A3: natural gas steam turbine | B3: 0 | C3: Same 2025-only rule as hard coal; per-state 2025 values on the Tuned tab.
A4: natural gas combined cycle | B4: 0 | C4: Same 2025-only rule as hard coal; per-state 2025 values on the Tuned tab and the pin table.
A5: nuclear | B5: 1 | C5: Structural must-run convention inherited from eps-us.
A6: hydro | B6: 0.9 | C6: Long-standing 0.90 convention, enforced as a MAX by the Keys hydro_guarantee_cap (Olivia 2026-08-13). Exceptions: SD 0.75 and WA 0.0 on the Tuned tab; VT year-varying ramp in the Keys F:G block; 12 crowd-out states carry an UNCAPPED 2025-only pin (Keys I:J, 2026-08-24) so the start year matches EIA-923 while HOC governs 2026+.
A7: onshore wind | B7: 0 | C7: VRE dispatches through the RPS/least-cost passes; no guarantee.
A8: solar PV | B8: 0 | C8: VRE dispatches through the RPS/least-cost passes; no guarantee.
A9: solar thermal | B9: 0 | C9: VRE dispatches through the RPS/least-cost passes; no guarantee.
A10: biomass | B10: 1 | C10: Must-run convention inherited from eps-us.
A11: geothermal | B11: 1 | C11: Must-run convention inherited from eps-us.
A12: petroleum | B12: 1 | C12: Fallback only: every state carries a computed per-state value on the Tuned tab, applied in ALL years (the documented exception to the 2025-only rule, Olivia 2026-08-26). The old eps-us must-run 1.0 would dispatch oil at natural-gas-peaker rates now that SYSHECF mirrors the peaker (+105% vs EIA-923 2025 nationally).
A13: natural gas peaker | B13: 1 | C13: Structural convention alongside nuclear/hydro, not calibration. Exceptions (MT/ND/VA/WA/WV) on the Tuned tab; ND also has a 2025 pin.
... A25: hydrogen combined cycle | B25: 0 | C25: ZEROED 2026-08-21 (Olivia): fleet does not exist in the 2025 start year; previous value (1) was the eps-us national template, not a state calibration. Zero lets least-cost dispatch decide if this tech is ever built in a policy scenario instead of forcing near-must-run operation.

Sheet Tuned
A1: state | B1: tech | C1: tuned_value | D1: key (state|tech) | E1: note
A2: AL | B2: natural gas combined cycle | C2: 0.306196 | D2: AL|natural gas combined cycle | E2: 2026-09-02 cross-state dispatch retune rounds 7-8 (same directive and method as the round-1-6 states): NGCC floor 0.148665 -> 0.3062 closes the last tunable opposite-sign split -- coal -0.7% / gas -1.3% / hydro and solar 0.0%. Round CSVs: qc/calibration/dispatch_retune_0902_round{7,8}.csv.
A3: AL | B3: petroleum | C3: 0.4912 | D3: AL|petroleum | E3: ALL YEARS (2025-only rule exception, Olivia 2026-08-26): oil-fired gen 2025 7.5 GWh / (cap 42.6 MW x CF 0.0411 x 8760) = 0.4912
A4: AR | B4: natural gas combined cycle | C4: 0.7 | D4: AR|natural gas combined cycle | E4: 2026-08-31 post-MCF retune (docs/findings/dispatch-recalibration-post-mcf-2026-08-31.md): floors re-solved from zero after the firm-credit MCF derate (0.9 thermal / 0.95 NGCC) invalidated the 08-28 values. One lever per state (NGCC or hard coal), balance-point target, secant; AR/FL/MS hand-interpolated on coal_err=gas_err (0.7/0.5/0.854). Source: qc/calibration/bgdpbes_0831_round3.csv + the finding doc final-floor table. RESTORED 2026-09-01 after the 08:36 InputData sync wiped the run trees (docs/findings/bau-0901-floor-revert-2026-09-01.md); VT excluded throughout (bad distributed-solar inputs).
A5: AR | B5: petroleum | C5: 1 | D5: AR|petroleum | E5: ALL YEARS (2025-only rule exception, Olivia 2026-08-26): oil-fired gen 2025 43.9 GWh / (cap 9.0 MW x CF 0.1014 x 8760) = 5.4865 -- CLIPPED at 1.0; 43.9 GWh of this burns at units whose capacity BHRaSYC books under another row, so it is unreachable
A6: AZ | B6: hard coal | C6: 0.649134 | D6: AZ|hard coal | E6: 2026-08-31 post-MCF retune (docs/findings/dispatch-recalibration-post-mcf-2026-08-31.md): floors re-solved from zero after the firm-credit MCF derate (0.9 thermal / 0.95 NGCC) invalidated the 08-28 values. One lever per state (NGCC or hard coal), balance-point target, secant; AR/FL/MS hand-interpolated on coal_err=gas_err (0.7/0.5/0.854). Source: qc/calibration/bgdpbes_0831_round3.csv + the finding doc final-floor table. RESTORED 2026-09-01 after the 08:36 InputData sync wiped the run trees (docs/findings/bau-0901-floor-revert-2026-09-01.md); VT excluded throughout (bad distributed-solar inputs).
A7: AZ | B7: petroleum | C7: 0.625 | D7: AZ|petroleum | E7: ALL YEARS (2025-only rule exception, Olivia 2026-08-26): oil-fired gen 2025 40.8 GWh / (cap 84.7 MW x CF 0.0880 x 8760) = 0.6250
A8: CA | B8: petroleum | C8: 0.3235 | D8: CA|petroleum | E8: ALL YEARS (2025-only rule exception, Olivia 2026-08-26): oil-fired gen 2025 31.1 GWh / (cap 224.0 MW x CF 0.0491 x 8760) = 0.3235
A9: CO | B9: natural gas combined cycle | C9: 0.92054 | D9: CO|natural gas combined cycle | E9: 2026-08-31 post-MCF retune (docs/findings/dispatch-recalibration-post-mcf-2026-08-31.md): floors re-solved from zero after the firm-credit MCF derate (0.9 thermal / 0.95 NGCC) invalidated the 08-28 values. One lever per state (NGCC or hard coal), balance-point target, secant; AR/FL/MS hand-interpolated on coal_err=gas_err (0.7/0.5/0.854). Source: qc/calibration/bgdpbes_0831_round3.csv + the finding doc final-floor table. RESTORED 2026-09-01 after the 08:36 InputData sync wiped the run trees (docs/findings/bau-0901-floor-revert-2026-09-01.md); VT excluded throughout (bad distributed-solar inputs).
A10: CO | B10: petroleum | C10: 0.087 | D10: CO|petroleum | E10: ALL YEARS (2025-only rule exception, Olivia 2026-08-26): oil-fired gen 2025 13.5 GWh / (cap 148.1 MW x CF 0.1198 x 8760) = 0.0870
A11: CT | B11: natural gas combined cycle | C11: 0.96805 | D11: CT|natural gas combined cycle | E11: 2026-08-31 post-MCF retune (docs/findings/dispatch-recalibration-post-mcf-2026-08-31.md): floors re-solved from zero after the firm-credit MCF derate (0.9 thermal / 0.95 NGCC) invalidated the 08-28 values. One lever per state (NGCC or hard coal), balance-point target, secant; AR/FL/MS hand-interpolated on coal_err=gas_err (0.7/0.5/0.854). Source: qc/calibration/bgdpbes_0831_round3.csv + the finding doc final-floor table. RESTORED 2026-09-01 after the 08:36 InputData sync wiped the run trees (docs/findings/bau-0901-floor-revert-2026-09-01.md); VT excluded throughout (bad distributed-solar inputs).
A12: CT | B12: petroleum | C12: 0.3608 | D12: CT|petroleum | E12: ALL YEARS (2025-only rule exception, Olivia 2026-08-26): oil-fired gen 2025 240.2 GWh / (cap 2197.2 MW x CF 0.0346 x 8760) = 0.3608
A13: DE | B13: petroleum | C13: 1 | D13: DE|petroleum | E13: ALL YEARS (2025-only rule exception, Olivia 2026-08-26): oil-fired gen 2025 71.4 GWh / (cap 111.1 MW x CF 0.0608 x 8760) = 1.2064 -- CLIPPED at 1.0; 74.0 GWh of this burns at units whose capacity BHRaSYC books under another row, so it is unreachable
... A100: WY | B100: petroleum | C100: 1 | D100: WY|petroleum | E100: ALL YEARS (2025-only rule exception, Olivia 2026-08-26): oil-fired gen 2025 52.7 GWh / (cap 4.7 MW x CF 0.0970 x 8760) = 13.1908 -- CLIPPED at 1.0; 52.4 GWh of this burns at units whose capacity BHRaSYC books under another row, so it is unreachable

Sheet Fleet
A1: FLEET SCREEN -- start-year (2025) electricity generation capacity by state and tech, MW
A2: Why: the four coal/gas guarantees are 2025-only, so a guarantee on a tech with no 2025 fleet is inert AND misleading. The BGDPbES tab multiplies those four rows by the has_fleet flag at the bottom of this tab.
A4: SOURCE AND PROVENANCE
A5: source file pattern | B5: state-eps-data/<ST>/elec/BHRaSYC/BHRaSYC-StartYearCapacities.csv
A6: handling | B6: summed across all Vintage columns per tech row; verbatim otherwise
A7: states read | B7: 48
A8: accessed | B8: 2026-09-02
A9: note | B9: BHRaSYC is generated outside this repo, so it is read from the deployed tree. Not circular: it is a different variable, so no BGDPbES value can be fed back into a rebuild.
A11: PER-FILE PROVENANCE
A12: state | B12: bytes | C12: sha256 (12) | D12: vintage cols | E12: tech rows
A13: AL | B13: 34670 | C13: aa554e6117ee | D13: 210 | E13: 24
A14: AR | B14: 34605 | C14: b9fb75c5c686 | D14: 210 | E14: 24
A15: AZ | B15: 34670 | C15: 221490253617 | D15: 210 | E15: 24
A16: CA | B16: 34935 | C16: 7af171e7c975 | D16: 210 | E16: 24
A17: CO | B17: 34660 | C17: 27074de39c39 | D17: 210 | E17: 24
A18: CT | B18: 34599 | C18: f8a2189f707c | D18: 210 | E18: 24
A19: DE | B19: 34554 | C19: a9513e0f983f | D19: 210 | E19: 24
A20: FL | B20: 34777 | C20: 013ebcbe3215 | D20: 210 | E20: 24
A21: GA | B21: 34671 | C21: 52641aea61a6 | D21: 210 | E21: 24
A22: IA | B22: 34659 | C22: f3053fb669a5 | D22: 210 | E22: 24
A23: ID | B23: 34620 | C23: 28c133c4ac92 | D23: 210 | E23: 24
A24: IL | B24: 34671 | C24: 96e03f983a73 | D24: 210 | E24: 24
... A60: WY | B60: 34596 | C60: 13185dd4cac1 | D60: 210 | E60: 24
A62: START-YEAR CAPACITY BY STATE AND TECH (MW)
A63: state | B63: hard coal | C63: natural gas steam turbine | D63: natural gas combined cycle | E63: nuclear | F63: hydro | G63: onshore wind | H63: solar PV | I63: solar thermal | J63: biomass | K63: geothermal | L63: petroleum | M63: natural gas peaker | N63: lignite | O63: offshore wind | P63: crude oil | Q63: heavy or residual fuel oil | R63: municipal solid waste | S63: hard coal w CCS | T63: natural gas combined cycle w CCS | U63: biomass w CCS | V63: lignite w CCS | W63: small modular reactor | X63: hydrogen combustion turbine | Y63: hydrogen combined cycle
A64: AL | B64: 4728 | C64: 1696.1 | D64: 11072 | E64: 5452.7 | F64: 3290.6 | G64: 0 | H64: 663.5 | I64: 0 | J64: 6.4 | K64: 0 | L64: 42.6 | M64: 3220.2 | N64: 0 | O64: 0 | P64: 797.6 | Q64: 0 | R64: 0 | S64: 0 | T64: 0 | U64: 0 | V64: 0 | W64: 0 | X64: 0 | Y64: 0
A65: AR | B65: 4729.6 | C65: 656 | D65: 4608.2 | E65: 1821 | F65: 1264.5 | G65: 0 | H65: 1772.46 | I65: 0 | J65: 8.8 | K65: 0 | L65: 9 | M65: 715.6 | N65: 0 | O65: 0 | P65: 280.4 | Q65: 0 | R65: 0 | S65: 0 | T65: 0 | U65: 0 | V65: 0 | W65: 0 | X65: 0 | Y65: 0
A66: AZ | B66: 2936 | C66: 1095 | D66: 10116.1 | E66: 3937 | F66: 2720.6 | G66: 1234.5 | H66: 4730.2 | I66: 295.6 | J66: 27.9 | K66: 0 | L66: 84.7 | M66: 3303.1 | N66: 0 | O66: 0 | P66: 58.5 | Q66: 0 | R66: 0 | S66: 0 | T66: 0 | U66: 0 | V66: 0 | W66: 0 | X66: 0 | Y66: 0
A67: CA | B67: 0 | C67: 3730.7 | D67: 19425.3 | E67: 2240 | F67: 10207.4 | G67: 6428.7 | H67: 21087.25 | I67: 917.8 | J67: 572.9 | K67: 1881.2 | L67: 224 | M67: 11157.1 | N67: 0 | O67: 0 | P67: 3212.72 | Q67: 0 | R67: 0 | S67: 0 | T67: 0 | U67: 0 | V67: 0 | W67: 0 | X67: 0 | Y67: 0
A68: CO | B68: 3786 | C68: 364 | D68: 3219.5 | E68: 0 | F68: 689.4 | G68: 5334.9 | H68: 2349.54 | I68: 0 | J68: 28.7 | K68: 0 | L68: 148.1 | M68: 2862.12 | N68: 0 | O68: 0 | P68: 114.72 | Q68: 0 | R68: 0 | S68: 0 | T68: 0 | U68: 0 | V68: 0 | W68: 0 | X68: 0 | Y68: 0
A69: CT | B69: 0 | C69: 434 | D69: 3835.18 | E69: 2104.2 | F69: 119.2 | G69: 5 | H69: 314.2 | I69: 0 | J69: 39.1 | K69: 0 | L69: 2197.2 | M69: 497.69 | N69: 0 | O69: 0 | P69: 226.85 | Q69: 0 | R69: 100.5 | S69: 0 | T69: 0 | U69: 0 | V69: 0 | W69: 0 | X69: 0 | Y69: 0
A70: DE | B70: 410 | C70: 695 | D70: 1496 | E70: 0 | F70: 0 | G70: 0 | H70: 91.9 | I70: 0 | J70: 10 | K70: 0 | L70: 111.1 | M70: 184 | N70: 0 | O70: 0 | P70: 276.2 | Q70: 0 | R70: 0 | S70: 0 | T70: 0 | U70: 0 | V70: 0 | W70: 0 | X70: 0 | Y70: 0
A71: FL | B71: 3564.7 | C71: 5418.9 | D71: 35819.7 | E71: 3666 | F71: 43.5 | G71: 0 | H71: 10942.9 | I71: 0 | J71: 271.8 | K71: 0 | L71: 1594.9 | M71: 8838.2 | N71: 0 | O71: 0 | P71: 1025.1 | Q71: 0 | R71: 250.5 | S71: 0 | T71: 0 | U71: 0 | V71: 0 | W71: 0 | X71: 0 | Y71: 0
A72: GA | B72: 5780 | C72: 724 | D72: 8090.8 | E72: 6289 | F72: 1979.9 | G72: 0 | H72: 4999.4 | I72: 0 | J72: 294.3 | K72: 0 | L72: 1014.3 | M72: 7363.7 | N72: 0 | O72: 0 | P72: 1166.75 | Q72: 0 | R72: 0 | S72: 0 | T72: 0 | U72: 0 | V72: 0 | W72: 0 | X72: 0 | Y72: 0
A73: IA | B73: 4392.9 | C73: 470.8 | D73: 1700.7 | E73: 0 | F73: 209.4 | G73: 12864.5 | H73: 676.1 | I73: 0 | J73: 16.2 | K73: 0 | L73: 775.9 | M73: 1364.94 | N73: 0 | O73: 0 | P73: 744.4 | Q73: 0 | R73: 0 | S73: 0 | T73: 0 | U73: 0 | V73: 0 | W73: 0 | X73: 0 | Y73: 0
A74: ID | B74: 0 | C74: 0 | D74: 515.43 | E74: 0 | F74: 2653.76 | G74: 1128.3 | H74: 500 | I74: 0 | J74: 26.4 | K74: 10 | L74: 5.58 | M74: 568.96 | N74: 0 | O74: 0 | P74: 98.9 | Q74: 0 | R74: 0 | S74: 0 | T74: 0 | U74: 0 | V74: 0 | W74: 0 | X74: 0 | Y74: 0
A75: IL | B75: 6356.7 | C75: 28.2 | D75: 5449.2 | E75: 11591.6 | F75: 31.7 | G75: 7872 | H75: 2955 | I75: 0 | J75: 55.2 | K75: 0 | L75: 650 | M75: 10372.1 | N75: 0 | O75: 0 | P75: 817.14 | Q75: 0 | R75: 0 | S75: 0 | T75: 0 | U75: 0 | V75: 0 | W75: 0 | X75: 0 | Y75: 0
... A111: WY | B111: 4928 | C111: 1317 | D111: 94 | E111: 0 | F111: 307.1 | G111: 3603.9 | H111: 242 | I111: 0 | J111: 0 | K111: 0 | L111: 4.7 | M111: 145 | N111: 0 | O111: 0 | P111: 203.8 | Q111: 0 | R111: 0 | S111: 0 | T111: 0 | U111: 0 | V111: 0 | W111: 0 | X111: 0 | Y111: 0
A113: CHECK: 48-state total (MW) -- an identity, so any nonzero difference is real
A114: sum of state rows | B114: =SUM(B64:B111) -> 167137.16 | C114: =SUM(C64:C111) -> 71978.44 | D114: =SUM(D64:D111) -> 283151.06 | E114: =SUM(E64:E111) -> 98391.2 | F114: =SUM(F64:F111) -> 79169.28 | G114: =SUM(G64:G111) -> 151487.37 | H114: =SUM(H64:H111) -> 120824.11 | I114: =SUM(I64:I111) -> 1392 | ... Y114: =SUM(Y64:Y111) -> 0
...

Sheet BGDPbES
A1: BAU Guaranteed Dispatch (dimensionless) | B1: 2021 | C1: 2022 | D1: 2023 | E1: 2024 | F1: 2025 | G1: 2026 | H1: 2027 | I1: 2028 | J1: 2029 | K1: 2030 | L1: 2031 | M1: 2032 | N1: 2033 | O1: 2034 | P1: 2035 | Q1: 2036 | R1: 2037 | S1: 2038 | T1: 2039 | U1: 2040 | V1: 2041 | W1: 2042 | X1: 2043 | Y1: 2044 | Z1: 2045 | AA1: 2046 | AB1: 2047 | AC1: 2048 | AD1: 2049 | AE1: 2050
A2: hard coal | B2: 0 | C2: 0 | D2: 0 | E2: 0 | F2: =IFERROR(INDEX(Keys!$J$2:$J$21,MATCH(About!$B$2&"|"&$A2,Keys!$I$2:$I$21,0)),IFERROR(INDEX(Tuned!$C$2:$C$100,MATCH(About!$B$2&"|"&$A2,Tuned!$D$2:$D$100,0)),INDEX(Defaults!$B$2:$B$25,MATCH($A2,Defaults!$A$2:$A$25,0))))*INDEX(Fleet!$C$118:$C$141,MATCH($A2,Fleet!$A$118:$A$141,0)) -> 0 | G2: 0 | H2: 0 | I2: 0 | J2: 0 | K2: 0 | L2: 0 | M2: 0 | N2: 0 | O2: 0 | P2: 0 | Q2: 0 | R2: 0 | S2: 0 | T2: 0 | U2: 0 | V2: 0 | W2: 0 | X2: 0 | Y2: 0 | Z2: 0 | AA2: 0 | AB2: 0 | AC2: 0 | AD2: 0 | AE2: 0
A3: natural gas steam turbine | B3: 0 | C3: 0 | D3: 0 | E3: 0 | F3: =IFERROR(INDEX(Keys!$J$2:$J$21,MATCH(About!$B$2&"|"&$A3,Keys!$I$2:$I$21,0)),IFERROR(INDEX(Tuned!$C$2:$C$100,MATCH(About!$B$2&"|"&$A3,Tuned!$D$2:$D$100,0)),INDEX(Defaults!$B$2:$B$25,MATCH($A3,Defaults!$A$2:$A$25,0))))*INDEX(Fleet!$C$118:$C$141,MATCH($A3,Fleet!$A$118:$A$141,0)) -> 0 | G3: 0 | H3: 0 | I3: 0 | J3: 0 | K3: 0 | L3: 0 | M3: 0 | N3: 0 | O3: 0 | P3: 0 | Q3: 0 | R3: 0 | S3: 0 | T3: 0 | U3: 0 | V3: 0 | W3: 0 | X3: 0 | Y3: 0 | Z3: 0 | AA3: 0 | AB3: 0 | AC3: 0 | AD3: 0 | AE3: 0
A4: natural gas combined cycle | B4: 0 | C4: 0 | D4: 0 | E4: 0 | F4: =IFERROR(INDEX(Keys!$J$2:$J$21,MATCH(About!$B$2&"|"&$A4,Keys!$I$2:$I$21,0)),IFERROR(INDEX(Tuned!$C$2:$C$100,MATCH(About!$B$2&"|"&$A4,Tuned!$D$2:$D$100,0)),INDEX(Defaults!$B$2:$B$25,MATCH($A4,Defaults!$A$2:$A$25,0))))*INDEX(Fleet!$C$118:$C$141,MATCH($A4,Fleet!$A$118:$A$141,0)) -> 0 | G4: 0 | H4: 0 | I4: 0 | J4: 0 | K4: 0 | L4: 0 | M4: 0 | N4: 0 | O4: 0 | P4: 0 | Q4: 0 | R4: 0 | S4: 0 | T4: 0 | U4: 0 | V4: 0 | W4: 0 | X4: 0 | Y4: 0 | Z4: 0 | AA4: 0 | AB4: 0 | AC4: 0 | AD4: 0 | AE4: 0
A5: nuclear | B5: =IFERROR(INDEX(Tuned!$C$2:$C$100,MATCH(About!$B$2&"|"&$A5,Tuned!$D$2:$D$100,0)),INDEX(Defaults!$B$2:$B$25,MATCH($A5,Defaults!$A$2:$A$25,0))) -> 1 | C5: =$B5 -> 1 | D5: =$B5 -> 1 | E5: =$B5 -> 1 | F5: =$B5 -> 1 | G5: =$B5 -> 1 | H5: =$B5 -> 1 | I5: =$B5 -> 1 | J5: =$B5 -> 1 | ... AE5: =$B5 -> 1
A6: hydro | B6: =IF(About!$B$2=Keys!$C$2,INDEX(Keys!$G$2:$G$31,MATCH(B$1,Keys!$F$2:$F$31,0)),MIN(IFERROR(INDEX(Tuned!$C$2:$C$100,MATCH(About!$B$2&"|"&$A6,Tuned!$D$2:$D$100,0)),INDEX(Defaults!$B$2:$B$25,MATCH($A6,Defaults!$A$2:$A$25,0))),Keys!$C$3)) -> 0 | C6: =IF(About!$B$2=Keys!$C$2,INDEX(Keys!$G$2:$G$31,MATCH(C$1,Keys!$F$2:$F$31,0)),IF(C$1=Keys!$C$4,IFERROR(INDEX(Keys!$J$2:$J$21,MATCH(About!$B$2&"|"&$A6,Keys!$I$2:$I$21,0)),$B6),$B6)) -> 0 | D6: =IF(About!$B$2=Keys!$C$2,INDEX(Keys!$G$2:$G$31,MATCH(D$1,Keys!$F$2:$F$31,0)),IF(D$1=Keys!$C$4,IFERROR(INDEX(Keys!$J$2:$J$21,MATCH(About!$B$2&"|"&$A6,Keys!$I$2:$I$21,0)),$B6),$B6)) -> 0 | E6: =IF(About!$B$2=Keys!$C$2,INDEX(Keys!$G$2:$G$31,MATCH(E$1,Keys!$F$2:$F$31,0)),IF(E$1=Keys!$C$4,IFERROR(INDEX(Keys!$J$2:$J$21,MATCH(About!$B$2&"|"&$A6,Keys!$I$2:$I$21,0)),$B6),$B6)) -> 0 | F6: =IF(About!$B$2=Keys!$C$2,INDEX(Keys!$G$2:$G$31,MATCH(F$1,Keys!$F$2:$F$31,0)),IF(F$1=Keys!$C$4,IFERROR(INDEX(Keys!$J$2:$J$21,MATCH(About!$B$2&"|"&$A6,Keys!$I$2:$I$21,0)),$B6),$B6)) -> 0 | G6: =IF(About!$B$2=Keys!$C$2,INDEX(Keys!$G$2:$G$31,MATCH(G$1,Keys!$F$2:$F$31,0)),IF(G$1=Keys!$C$4,IFERROR(INDEX(Keys!$J$2:$J$21,MATCH(About!$B$2&"|"&$A6,Keys!$I$2:$I$21,0)),$B6),$B6)) -> 0.3 | H6: =IF(About!$B$2=Keys!$C$2,INDEX(Keys!$G$2:$G$31,MATCH(H$1,Keys!$F$2:$F$31,0)),IF(H$1=Keys!$C$4,IFERROR(INDEX(Keys!$J$2:$J$21,MATCH(About!$B$2&"|"&$A6,Keys!$I$2:$I$21,0)),$B6),$B6)) -> 0.5 | I6: =IF(About!$B$2=Keys!$C$2,INDEX(Keys!$G$2:$G$31,MATCH(I$1,Keys!$F$2:$F$31,0)),IF(I$1=Keys!$C$4,IFERROR(INDEX(Keys!$J$2:$J$21,MATCH(About!$B$2&"|"&$A6,Keys!$I$2:$I$21,0)),$B6),$B6)) -> 0.7 | J6: =IF(About!$B$2=Keys!$C$2,INDEX(Keys!$G$2:$G$31,MATCH(J$1,Keys!$F$2:$F$31,0)),IF(J$1=Keys!$C$4,IFERROR(INDEX(Keys!$J$2:$J$21,MATCH(About!$B$2&"|"&$A6,Keys!$I$2:$I$21,0)),$B6),$B6)) -> 0.85 | ... AE6: =IF(About!$B$2=Keys!$C$2,INDEX(Keys!$G$2:$G$31,MATCH(AE$1,Keys!$F$2:$F$31,0)),IF(AE$1=Keys!$C$4,IFERROR(INDEX(Keys!$J$2:$J$21,MATCH(About!$B$2&"|"&$A6,Keys!$I$2:$I$21,0)),$B6),$B6)) -> 0.9
A7: onshore wind | B7: =IFERROR(INDEX(Tuned!$C$2:$C$100,MATCH(About!$B$2&"|"&$A7,Tuned!$D$2:$D$100,0)),INDEX(Defaults!$B$2:$B$25,MATCH($A7,Defaults!$A$2:$A$25,0))) -> 0 | C7: =IF(C$1=Keys!$C$4,IFERROR(INDEX(Keys!$J$2:$J$21,MATCH(About!$B$2&"|"&$A7,Keys!$I$2:$I$21,0)),$B7),$B7) -> 0 | D7: =IF(D$1=Keys!$C$4,IFERROR(INDEX(Keys!$J$2:$J$21,MATCH(About!$B$2&"|"&$A7,Keys!$I$2:$I$21,0)),$B7),$B7) -> 0 | E7: =IF(E$1=Keys!$C$4,IFERROR(INDEX(Keys!$J$2:$J$21,MATCH(About!$B$2&"|"&$A7,Keys!$I$2:$I$21,0)),$B7),$B7) -> 0 | F7: =IF(F$1=Keys!$C$4,IFERROR(INDEX(Keys!$J$2:$J$21,MATCH(About!$B$2&"|"&$A7,Keys!$I$2:$I$21,0)),$B7),$B7) -> 0 | G7: =IF(G$1=Keys!$C$4,IFERROR(INDEX(Keys!$J$2:$J$21,MATCH(About!$B$2&"|"&$A7,Keys!$I$2:$I$21,0)),$B7),$B7) -> 0 | H7: =IF(H$1=Keys!$C$4,IFERROR(INDEX(Keys!$J$2:$J$21,MATCH(About!$B$2&"|"&$A7,Keys!$I$2:$I$21,0)),$B7),$B7) -> 0 | I7: =IF(I$1=Keys!$C$4,IFERROR(INDEX(Keys!$J$2:$J$21,MATCH(About!$B$2&"|"&$A7,Keys!$I$2:$I$21,0)),$B7),$B7) -> 0 | J7: =IF(J$1=Keys!$C$4,IFERROR(INDEX(Keys!$J$2:$J$21,MATCH(About!$B$2&"|"&$A7,Keys!$I$2:$I$21,0)),$B7),$B7) -> 0 | ... AE7: =IF(AE$1=Keys!$C$4,IFERROR(INDEX(Keys!$J$2:$J$21,MATCH(About!$B$2&"|"&$A7,Keys!$I$2:$I$21,0)),$B7),$B7) -> 0
A8: solar PV | B8: =IFERROR(INDEX(Tuned!$C$2:$C$100,MATCH(About!$B$2&"|"&$A8,Tuned!$D$2:$D$100,0)),INDEX(Defaults!$B$2:$B$25,MATCH($A8,Defaults!$A$2:$A$25,0))) -> 0 | C8: =IF(C$1=Keys!$C$4,IFERROR(INDEX(Keys!$J$2:$J$21,MATCH(About!$B$2&"|"&$A8,Keys!$I$2:$I$21,0)),$B8),$B8) -> 0 | D8: =IF(D$1=Keys!$C$4,IFERROR(INDEX(Keys!$J$2:$J$21,MATCH(About!$B$2&"|"&$A8,Keys!$I$2:$I$21,0)),$B8),$B8) -> 0 | E8: =IF(E$1=Keys!$C$4,IFERROR(INDEX(Keys!$J$2:$J$21,MATCH(About!$B$2&"|"&$A8,Keys!$I$2:$I$21,0)),$B8),$B8) -> 0 | F8: =IF(F$1=Keys!$C$4,IFERROR(INDEX(Keys!$J$2:$J$21,MATCH(About!$B$2&"|"&$A8,Keys!$I$2:$I$21,0)),$B8),$B8) -> 1 | G8: =IF(G$1=Keys!$C$4,IFERROR(INDEX(Keys!$J$2:$J$21,MATCH(About!$B$2&"|"&$A8,Keys!$I$2:$I$21,0)),$B8),$B8) -> 0 | H8: =IF(H$1=Keys!$C$4,IFERROR(INDEX(Keys!$J$2:$J$21,MATCH(About!$B$2&"|"&$A8,Keys!$I$2:$I$21,0)),$B8),$B8) -> 0 | I8: =IF(I$1=Keys!$C$4,IFERROR(INDEX(Keys!$J$2:$J$21,MATCH(About!$B$2&"|"&$A8,Keys!$I$2:$I$21,0)),$B8),$B8) -> 0 | J8: =IF(J$1=Keys!$C$4,IFERROR(INDEX(Keys!$J$2:$J$21,MATCH(About!$B$2&"|"&$A8,Keys!$I$2:$I$21,0)),$B8),$B8) -> 0 | ... AE8: =IF(AE$1=Keys!$C$4,IFERROR(INDEX(Keys!$J$2:$J$21,MATCH(About!$B$2&"|"&$A8,Keys!$I$2:$I$21,0)),$B8),$B8) -> 0
A9: solar thermal | B9: =IFERROR(INDEX(Tuned!$C$2:$C$100,MATCH(About!$B$2&"|"&$A9,Tuned!$D$2:$D$100,0)),INDEX(Defaults!$B$2:$B$25,MATCH($A9,Defaults!$A$2:$A$25,0))) -> 0 | C9: =$B9 -> 0 | D9: =$B9 -> 0 | E9: =$B9 -> 0 | F9: =$B9 -> 0 | G9: =$B9 -> 0 | H9: =$B9 -> 0 | I9: =$B9 -> 0 | J9: =$B9 -> 0 | ... AE9: =$B9 -> 0
A10: biomass | B10: =IFERROR(INDEX(Tuned!$C$2:$C$100,MATCH(About!$B$2&"|"&$A10,Tuned!$D$2:$D$100,0)),INDEX(Defaults!$B$2:$B$25,MATCH($A10,Defaults!$A$2:$A$25,0))) -> 1 | C10: =$B10 -> 1 | D10: =$B10 -> 1 | E10: =$B10 -> 1 | F10: =$B10 -> 1 | G10: =$B10 -> 1 | H10: =$B10 -> 1 | I10: =$B10 -> 1 | J10: =$B10 -> 1 | ... AE10: =$B10 -> 1
A11: geothermal | B11: =IFERROR(INDEX(Tuned!$C$2:$C$100,MATCH(About!$B$2&"|"&$A11,Tuned!$D$2:$D$100,0)),INDEX(Defaults!$B$2:$B$25,MATCH($A11,Defaults!$A$2:$A$25,0))) -> 1 | C11: =$B11 -> 1 | D11: =$B11 -> 1 | E11: =$B11 -> 1 | F11: =$B11 -> 1 | G11: =$B11 -> 1 | H11: =$B11 -> 1 | I11: =$B11 -> 1 | J11: =$B11 -> 1 | ... AE11: =$B11 -> 1
A12: petroleum | B12: =IFERROR(INDEX(Tuned!$C$2:$C$100,MATCH(About!$B$2&"|"&$A12,Tuned!$D$2:$D$100,0)),INDEX(Defaults!$B$2:$B$25,MATCH($A12,Defaults!$A$2:$A$25,0))) -> 0.0322 | C12: =$B12 -> 0.0322 | D12: =$B12 -> 0.0322 | E12: =$B12 -> 0.0322 | F12: =$B12 -> 0.0322 | G12: =$B12 -> 0.0322 | H12: =$B12 -> 0.0322 | I12: =$B12 -> 0.0322 | J12: =$B12 -> 0.0322 | ... AE12: =$B12 -> 0.0322
A13: natural gas peaker | B13: =INDEX(Defaults!$B$2:$B$25,MATCH($A13,Defaults!$A$2:$A$25,0)) -> 1 | C13: =INDEX(Defaults!$B$2:$B$25,MATCH($A13,Defaults!$A$2:$A$25,0)) -> 1 | D13: =INDEX(Defaults!$B$2:$B$25,MATCH($A13,Defaults!$A$2:$A$25,0)) -> 1 | E13: =INDEX(Defaults!$B$2:$B$25,MATCH($A13,Defaults!$A$2:$A$25,0)) -> 1 | F13: =IFERROR(INDEX(Tuned!$C$2:$C$100,MATCH(About!$B$2&"|"&$A13,Tuned!$D$2:$D$100,0)),INDEX(Defaults!$B$2:$B$25,MATCH($A13,Defaults!$A$2:$A$25,0))) -> 1 | G13: =INDEX(Defaults!$B$2:$B$25,MATCH($A13,Defaults!$A$2:$A$25,0)) -> 1 | H13: =INDEX(Defaults!$B$2:$B$25,MATCH($A13,Defaults!$A$2:$A$25,0)) -> 1 | I13: =INDEX(Defaults!$B$2:$B$25,MATCH($A13,Defaults!$A$2:$A$25,0)) -> 1 | J13: =INDEX(Defaults!$B$2:$B$25,MATCH($A13,Defaults!$A$2:$A$25,0)) -> 1 | K13: =INDEX(Defaults!$B$2:$B$25,MATCH($A13,Defaults!$A$2:$A$25,0)) -> 1 | L13: =INDEX(Defaults!$B$2:$B$25,MATCH($A13,Defaults!$A$2:$A$25,0)) -> 1 | M13: =INDEX(Defaults!$B$2:$B$25,MATCH($A13,Defaults!$A$2:$A$25,0)) -> 1 | N13: =INDEX(Defaults!$B$2:$B$25,MATCH($A13,Defaults!$A$2:$A$25,0)) -> 1 | ... AE13: =INDEX(Defaults!$B$2:$B$25,MATCH($A13,Defaults!$A$2:$A$25,0)) -> 1
A14: lignite | B14: 0 | C14: 0 | D14: 0 | E14: 0 | F14: =IFERROR(INDEX(Keys!$J$2:$J$21,MATCH(About!$B$2&"|"&$A14,Keys!$I$2:$I$21,0)),IFERROR(INDEX(Tuned!$C$2:$C$100,MATCH(About!$B$2&"|"&$A14,Tuned!$D$2:$D$100,0)),INDEX(Defaults!$B$2:$B$25,MATCH($A14,Defaults!$A$2:$A$25,0))))*INDEX(Fleet!$C$118:$C$141,MATCH($A14,Fleet!$A$118:$A$141,0)) -> 0 | G14: 0 | H14: 0 | I14: 0 | J14: 0 | K14: 0 | L14: 0 | M14: 0 | N14: 0 | O14: 0 | P14: 0 | Q14: 0 | R14: 0 | S14: 0 | T14: 0 | U14: 0 | V14: 0 | W14: 0 | X14: 0 | Y14: 0 | Z14: 0 | AA14: 0 | AB14: 0 | AC14: 0 | AD14: 0 | AE14: 0
A15: offshore wind | B15: =IFERROR(INDEX(Tuned!$C$2:$C$100,MATCH(About!$B$2&"|"&$A15,Tuned!$D$2:$D$100,0)),INDEX(Defaults!$B$2:$B$25,MATCH($A15,Defaults!$A$2:$A$25,0))) -> 0 | C15: =$B15 -> 0 | D15: =$B15 -> 0 | E15: =$B15 -> 0 | F15: =$B15 -> 0 | G15: =$B15 -> 0 | H15: =$B15 -> 0 | I15: =$B15 -> 0 | J15: =$B15 -> 0 | ... AE15: =$B15 -> 0
A16: crude oil | B16: =IFERROR(INDEX(Tuned!$C$2:$C$100,MATCH(About!$B$2&"|"&$A16,Tuned!$D$2:$D$100,0)),INDEX(Defaults!$B$2:$B$25,MATCH($A16,Defaults!$A$2:$A$25,0))) -> 1 | C16: =$B16 -> 1 | D16: =$B16 -> 1 | E16: =$B16 -> 1 | F16: =$B16 -> 1 | G16: =$B16 -> 1 | H16: =$B16 -> 1 | I16: =$B16 -> 1 | J16: =$B16 -> 1 | ... AE16: =$B16 -> 1
A17: heavy or residual fuel oil | B17: =IFERROR(INDEX(Tuned!$C$2:$C$100,MATCH(About!$B$2&"|"&$A17,Tuned!$D$2:$D$100,0)),INDEX(Defaults!$B$2:$B$25,MATCH($A17,Defaults!$A$2:$A$25,0))) -> 0 | C17: =$B17 -> 0 | D17: =$B17 -> 0 | E17: =$B17 -> 0 | F17: =$B17 -> 0 | G17: =$B17 -> 0 | H17: =$B17 -> 0 | I17: =$B17 -> 0 | J17: =$B17 -> 0 | ... AE17: =$B17 -> 0
A18: municipal solid waste | B18: =IFERROR(INDEX(Tuned!$C$2:$C$100,MATCH(About!$B$2&"|"&$A18,Tuned!$D$2:$D$100,0)),INDEX(Defaults!$B$2:$B$25,MATCH($A18,Defaults!$A$2:$A$25,0))) -> 0 | C18: =$B18 -> 0 | D18: =$B18 -> 0 | E18: =$B18 -> 0 | F18: =$B18 -> 0 | G18: =$B18 -> 0 | H18: =$B18 -> 0 | I18: =$B18 -> 0 | J18: =$B18 -> 0 | ... AE18: =$B18 -> 0
A19: hard coal w CCS | B19: =IFERROR(INDEX(Tuned!$C$2:$C$100,MATCH(About!$B$2&"|"&$A19,Tuned!$D$2:$D$100,0)),INDEX(Defaults!$B$2:$B$25,MATCH($A19,Defaults!$A$2:$A$25,0))) -> 0 | C19: =$B19 -> 0 | D19: =$B19 -> 0 | E19: =$B19 -> 0 | F19: =$B19 -> 0 | G19: =$B19 -> 0 | H19: =$B19 -> 0 | I19: =$B19 -> 0 | J19: =$B19 -> 0 | ... AE19: =$B19 -> 0
A20: natural gas combined cycle w CCS | B20: =IFERROR(INDEX(Tuned!$C$2:$C$100,MATCH(About!$B$2&"|"&$A20,Tuned!$D$2:$D$100,0)),INDEX(Defaults!$B$2:$B$25,MATCH($A20,Defaults!$A$2:$A$25,0))) -> 0 | C20: =$B20 -> 0 | D20: =$B20 -> 0 | E20: =$B20 -> 0 | F20: =$B20 -> 0 | G20: =$B20 -> 0 | H20: =$B20 -> 0 | I20: =$B20 -> 0 | J20: =$B20 -> 0 | ... AE20: =$B20 -> 0
A21: biomass w CCS | B21: =IFERROR(INDEX(Tuned!$C$2:$C$100,MATCH(About!$B$2&"|"&$A21,Tuned!$D$2:$D$100,0)),INDEX(Defaults!$B$2:$B$25,MATCH($A21,Defaults!$A$2:$A$25,0))) -> 0 | C21: =$B21 -> 0 | D21: =$B21 -> 0 | E21: =$B21 -> 0 | F21: =$B21 -> 0 | G21: =$B21 -> 0 | H21: =$B21 -> 0 | I21: =$B21 -> 0 | J21: =$B21 -> 0 | ... AE21: =$B21 -> 0
A22: lignite w CCS | B22: =IFERROR(INDEX(Tuned!$C$2:$C$100,MATCH(About!$B$2&"|"&$A22,Tuned!$D$2:$D$100,0)),INDEX(Defaults!$B$2:$B$25,MATCH($A22,Defaults!$A$2:$A$25,0))) -> 0 | C22: =$B22 -> 0 | D22: =$B22 -> 0 | E22: =$B22 -> 0 | F22: =$B22 -> 0 | G22: =$B22 -> 0 | H22: =$B22 -> 0 | I22: =$B22 -> 0 | J22: =$B22 -> 0 | ... AE22: =$B22 -> 0
A23: small modular reactor | B23: =IFERROR(INDEX(Tuned!$C$2:$C$100,MATCH(About!$B$2&"|"&$A23,Tuned!$D$2:$D$100,0)),INDEX(Defaults!$B$2:$B$25,MATCH($A23,Defaults!$A$2:$A$25,0))) -> 0 | C23: =$B23 -> 0 | D23: =$B23 -> 0 | E23: =$B23 -> 0 | F23: =$B23 -> 0 | G23: =$B23 -> 0 | H23: =$B23 -> 0 | I23: =$B23 -> 0 | J23: =$B23 -> 0 | ... AE23: =$B23 -> 0
A24: hydrogen combustion turbine | B24: =IFERROR(INDEX(Tuned!$C$2:$C$100,MATCH(About!$B$2&"|"&$A24,Tuned!$D$2:$D$100,0)),INDEX(Defaults!$B$2:$B$25,MATCH($A24,Defaults!$A$2:$A$25,0))) -> 1 | C24: =$B24 -> 1 | D24: =$B24 -> 1 | E24: =$B24 -> 1 | F24: =$B24 -> 1 | G24: =$B24 -> 1 | H24: =$B24 -> 1 | I24: =$B24 -> 1 | J24: =$B24 -> 1 | ... AE24: =$B24 -> 1
A25: hydrogen combined cycle | B25: =IFERROR(INDEX(Tuned!$C$2:$C$100,MATCH(About!$B$2&"|"&$A25,Tuned!$D$2:$D$100,0)),INDEX(Defaults!$B$2:$B$25,MATCH($A25,Defaults!$A$2:$A$25,0))) -> 0 | C25: =$B25 -> 0 | D25: =$B25 -> 0 | E25: =$B25 -> 0 | F25: =$B25 -> 0 | G25: =$B25 -> 0 | H25: =$B25 -> 0 | I25: =$B25 -> 0 | J25: =$B25 -> 0 | ... AE25: =$B25 -> 0
